Workbook
Name LISTA: Productos!$G$2:$G$3564

Sheet Productos
D1: IMAGEN | N1: Jul21-Mar22 | O1: Abr22-Feb23 | P1: Feb23-Mar24 | Q1: Mar24-Sep24 | R1: Sep24-Feb25 | S1: Lista Feb 2025 | W1: 0.05 | Z1: 0.1 | AC1: 0.15 | AF1: 0.17 | AI1: 0.2 | AL1: FORMULA QUE DEBE IR EN LA CELDA AN3 (DE AQUI SALEN LOS ESPEJOS =FILTER(A:AM,A:A=1) | AO1: IMAGEN | AY1: Ene21-Jun21 | AZ1: Jul21-Mar22 | BA1: Abr22-Feb23 | BB1: Feb23-Mar24 | BC1: Mar24-Sep24 | BD1: Lista 2024 oct | BH1: 0.05 | BK1: 0.1 | BN1: 0.15 | BQ1: 0.17 | BT1: 0.2
A2: V | B2: T | C2: C | D2: CLAVE | E2: UD | F2: LINEA | G2: DESCRIPCIÓN LARGA | H2: DESCRIPCIÓN CORTA | I2: C | J2: MIN | K2: MAX | L2: SISTEMAS | M2: VACIO | N2: PRECIO DE LISTA (1) | O2: PRECIO DE LISTA (1) | P2: PRECIO DE LISTA (1) | Q2: PRECIO DE LISTA (1) | R2: PRECIO DE LISTA (1) | S2: PRECIO DE LISTA (1) | T2: IVA | U2: TOTAL | V2: Dif respecto al precio anterior | W2: PRECIO MAYOREO (2) | X2: IVA | Y2: TOTAL | Z2: PRECIO MECÁNICOS (3) | AA2: IVA | AB2: TOTAL | AC2: PRECIO DISTRIBUIDOR A (4) | AD2: IVA | AE2: TOTAL | AF2: PRECIO DISTRIBUIDOR B (5) | AG2: IVA | AH2: TOTAL | AI2: PRECIO SUCURSAL (6) | AJ2: IVA | AK2: TOTAL | AL2: V | AM2: T | AN2: C | AO2: CLAVE | AP2: UD | AQ2: LINEA | AR2: DESCRIPCIÓN LARGA | AS2: DESCRIPCIÓN CORTA | AT2: C | AU2: MIN | AV2: MAX | AW2: SISTEMAS | AX2: VACIO | AY2: PRECIO DE LISTA (1) | AZ2: PRECIO DE LISTA (1) | BA2: PRECIO DE LISTA (1) | BB2: PRECIO DE LISTA (1) | BC2: PRECIO DE LISTA (1) | BD2: PRECIO DE LISTA (1) | BE2: IVA | BF2: TOTAL | BG2: Dif respecto al precio anterior | BH2: PRECIO MAYOREO (4) | BI2: IVA | BJ2: TOTAL | BK2: PRECIO MECÁNICOS (5) | BL2: IVA | BM2: TOTAL | BN2: PRECIO DISTRIBUIDOR A (6) | BO2: IVA | BP2: TOTAL | BQ2: PRECIO DISTRIBUIDOR B (7) | BR2: IVA | BS2: TOTAL | BT2: PRECIO SUCURSAL (8) | BU2: IVA | BV2: TOTAL
C3: E | D3: AB01 | E3: PZA | F3: WAL | G3: ABRAZADERA ACERO INOXIDABLE 6" CLAMP | I3: =IF(D3="","",LEN(H3)) -> 0 | O3: 1074 | P3: 1220 | Q3: 1220 | R3: 1281 | S3: 1345 | T3: =S3*0.16 -> 215.2 | U3: =S3+T3 -> 1560.2 | V3: =(S3-R3)/R3 -> 0.049960968 | W3: =(IF(B3="",(S3*(1-$W$1)),(IF(B3=1,(S3*(1-$W$1)),(IF(B3=2,(S3*(1-$W$1)),(IF(B3=3,(S3*(1-$W$1)),(IF(B3=4,(S3*(1)))))))))))) -> 1277.75 | X3: =W3*0.16 -> 204.44 | Y3: =W3+X3 -> 1482.19 | Z3: =(IF(B3="",(S3*(1-$Z$1)),(IF(B3=1,(S3*(1-$Z$1)),(IF(B3=2,(S3*(1-$Z$1)),(IF(B3=3,(S3*(1-$Z$1)),(IF(B3=4,(S3*(1)))))))))))) -> 1210.5 | AA3: =Z3*0.16 -> 193.68 | AB3: =Z3+AA3 -> 1404.18 | AC3: =(IF(B3="",(S3*(1-$AC$1)),(IF(B3=1,(S3*(1-$AC$1)),(IF(B3=2,(S3*(1-0.15)),(IF(B3=3,(S3*(1-0.1)),(IF(B3=4,(S3*(1)))))))))))) -> 1143.25 | AD3: =AC3*0.16 -> 182.92 | AE3: =AC3+AD3 -> 1326.17 | AF3: =(IF(B3="",(S3*(1-$AF$1)),(IF(B3=1,(S3*(1-$AF$1)),(IF(B3=2,(S3*(1-0.15)),(IF(B3=3,(S3*(1-0.1)),(IF(B3=4,(S3*(1)))))))))))) -> 1116.35 | AG3: =AF3*0.16 -> 178.616 | AH3: =AF3+AG3 -> 1294.966 | AI3: =(IF(B3="",(S3*(1-$AI$1)),(IF(B3=1,(S3*(1-$AI$1)),(IF(B3=2,(S3*(1-0.15)),(IF(B3=3,(S3*(1-0.1)),(IF(B3=4,(S3*(1)))))))))))) -> 1076 | AJ3: =AI3*0.16 -> 172.16 | AK3: =AI3+AJ3 -> 1248.16 | AL3: =IFERROR(__xludf.DUMMYFUNCTION("FILTER(A:AK,A:A=1)"),1.0) -> 1 | AN3: =IFERROR(__xludf.DUMMYFUNCTION("""COMPUTED_VALUE""")," C") -> C | AO3: =IFERROR(__xludf.DUMMYFUNCTION("""COMPUTED_VALUE""")," AC02") -> AC02 | AP3: =IFERROR(__xludf.DUMMYFUNCTION("""COMPUTED_VALUE""")," PZA") -> PZA | AQ3: =IFERROR(__xludf.DUMMYFUNCTION("""COMPUTED_VALUE""")," REF") -> REF | AR3: =IFERROR(__xludf.DUMMYFUNCTION("""COMPUTED_VALUE""")," ACEITE SAE BARDAHL 40") -> ACEITE SAE BARDAHL 40 | AS3: =IFERROR(__xludf.DUMMYFUNCTION("""COMPUTED_VALUE""")," ACEITE SAE BARDAHL 40") -> ACEITE SAE BARDAHL 40 | AT3: =IFERROR(__xludf.DUMMYFUNCTION("""COMPUTED_VALUE"""),21.0) -> 21 | AY3: =IFERROR(__xludf.DUMMYFUNCTION("""COMPUTED_VALUE"""),100.0) -> 100 | AZ3: =IFERROR(__xludf.DUMMYFUNCTION("""COMPUTED_VALUE"""),108.0) -> 108 | BA3: =IFERROR(__xludf.DUMMYFUNCTION("""COMPUTED_VALUE"""),134.78) -> 134.78 | BB3: =IFERROR(__xludf.DUMMYFUNCTION("""COMPUTED_VALUE"""),134.78) -> 134.78 | BC3: =IFERROR(__xludf.DUMMYFUNCTION("""COMPUTED_VALUE"""),130.0) -> 130 | BD3: =IFERROR(__xludf.DUMMYFUNCTION("""COMPUTED_VALUE"""),137.0) -> 137 | BE3: =IFERROR(__xludf.DUMMYFUNCTION("""COMPUTED_VALUE"""),21.92) -> 21.92 | BF3: =IFERROR(__xludf.DUMMYFUNCTION("""COMPUTED_VALUE"""),158.92000000000002) -> 158.92 | BG3: =IFERROR(__xludf.DUMMYFUNCTION("""COMPUTED_VALUE"""),0.05384615384615385) -> 0.053846154 | BH3: =IFERROR(__xludf.DUMMYFUNCTION("""COMPUTED_VALUE"""),130.15) -> 130.15 | BI3: =IFERROR(__xludf.DUMMYFUNCTION("""COMPUTED_VALUE"""),20.824) -> 20.824 | BJ3: =IFERROR(__xludf.DUMMYFUNCTION("""COMPUTED_VALUE"""),150.97400000000002) -> 150.974 | BK3: =IFERROR(__xludf.DUMMYFUNCTION("""COMPUTED_VALUE"""),123.3) -> 123.3 | BL3: =IFERROR(__xludf.DUMMYFUNCTION("""COMPUTED_VALUE"""),19.728) -> 19.728 | BM3: =IFERROR(__xludf.DUMMYFUNCTION("""COMPUTED_VALUE"""),143.028) -> 143.028 | BN3: =IFERROR(__xludf.DUMMYFUNCTION("""COMPUTED_VALUE"""),116.45) -> 116.45 | BO3: =IFERROR(__xludf.DUMMYFUNCTION("""COMPUTED_VALUE"""),18.632) -> 18.632 | BP3: =IFERROR(__xludf.DUMMYFUNCTION("""COMPUTED_VALUE"""),135.082) -> 135.082 | BQ3: =IFERROR(__xludf.DUMMYFUNCTION("""COMPUTED_VALUE"""),113.71) -> 113.71 | BR3: =IFERROR(__xludf.DUMMYFUNCTION("""COMPUTED_VALUE"""),18.1936) -> 18.1936 | BS3: =IFERROR(__xludf.DUMMYFUNCTION("""COMPUTED_VALUE"""),131.90359999999998) -> 131.9036 | BT3: =IFERROR(__xludf.DUMMYFUNCTION("""COMPUTED_VALUE"""),109.60000000000001) -> 109.6 | BU3: =IFERROR(__xludf.DUMMYFUNCTION("""COMPUTED_VALUE"""),17.536) -> 17.536 | BV3: =IFERROR(__xludf.DUMMYFUNCTION("""COMPUTED_VALUE"""),127.13600000000001) -> 127.136
C4: C | D4: AC01 | E4: PZA | F4: REF | G4: ACEITE ROSHFRANS ESTÁNDAR 250 | H4: ACEITE ROSHFRANS ESTANDAR 250 | I4: =IF(D4="","",LEN(H4)) -> 29 | N4: 88 | O4: 126 | P4: 136.08 | Q4: 136.08 | R4: 144 | S4: 151 | T4: =S4*0.16 -> 24.16 | U4: =S4+T4 -> 175.16 | V4: =(S4-R4)/R4 -> 0.048611111 | W4: =(IF(B4="",(S4*(1-$W$1)),(IF(B4=1,(S4*(1-$W$1)),(IF(B4=2,(S4*(1-$W$1)),(IF(B4=3,(S4*(1-$W$1)),(IF(B4=4,(S4*(1)))))))))))) -> 143.45 | X4: =W4*0.16 -> 22.952 | Y4: =W4+X4 -> 166.402 | Z4: =(IF(B4="",(S4*(1-$Z$1)),(IF(B4=1,(S4*(1-$Z$1)),(IF(B4=2,(S4*(1-$Z$1)),(IF(B4=3,(S4*(1-$Z$1)),(IF(B4=4,(S4*(1)))))))))))) -> 135.9 | AA4: =Z4*0.16 -> 21.744 | AB4: =Z4+AA4 -> 157.644 | AC4: =(IF(B4="",(S4*(1-$AC$1)),(IF(B4=1,(S4*(1-$AC$1)),(IF(B4=2,(S4*(1-0.15)),(IF(B4=3,(S4*(1-0.1)),(IF(B4=4,(S4*(1)))))))))))) -> 128.35 | AD4: =AC4*0.16 -> 20.536 | AE4: =AC4+AD4 -> 148.886 | AF4: =(IF(B4="",(S4*(1-$AF$1)),(IF(B4=1,(S4*(1-$AF$1)),(IF(B4=2,(S4*(1-0.15)),(IF(B4=3,(S4*(1-0.1)),(IF(B4=4,(S4*(1)))))))))))) -> 125.33 | AG4: =AF4*0.16 -> 20.0528 | AH4: =AF4+AG4 -> 145.3828 | AI4: =(IF(B4="",(S4*(1-$AI$1)),(IF(B4=1,(S4*(1-$AI$1)),(IF(B4=2,(S4*(1-0.15)),(IF(B4=3,(S4*(1-0.1)),(IF(B4=4,(S4*(1)))))))))))) -> 120.8 | AJ4: =AI4*0.16 -> 19.328 | AK4: =AI4+AJ4 -> 140.128 | AL4: =IFERROR(__xludf.DUMMYFUNCTION("""COMPUTED_VALUE"""),1.0) -> 1 | AM4: =IFERROR(__xludf.DUMMYFUNCTION("""COMPUTED_VALUE"""),2.0) -> 2 | AN4: =IFERROR(__xludf.DUMMYFUNCTION("""COMPUTED_VALUE""")," C") -> C | AO4: =IFERROR(__xludf.DUMMYFUNCTION("""COMPUTED_VALUE""")," AE01") -> AE01 | AP4: =IFERROR(__xludf.DUMMYFUNCTION("""COMPUTED_VALUE""")," PZA") -> PZA | AQ4: =IFERROR(__xludf.DUMMYFUNCTION("""COMPUTED_VALUE""")," REF") -> REF | AR4: =IFERROR(__xludf.DUMMYFUNCTION("""COMPUTED_VALUE""")," ACEITERA DE PIPETA FLEXIBLE 300 ML. TRUPER") -> ACEITERA DE PIPETA FLEXIBLE 300 ML. TRUPER | AS4: =IFERROR(__xludf.DUMMYFUNCTION("""COMPUTED_VALUE""")," ACEITERA PIPETA FLEXIBLE 300 ML TRUPER") -> ACEITERA PIPETA FLEXIBLE 300 ML TRUPER | AT4: =IFERROR(__xludf.DUMMYFUNCTION("""COMPUTED_VALUE"""),38.0) -> 38 | AY4: =IFERROR(__xludf.DUMMYFUNCTION("""COMPUTED_VALUE"""),103.0) -> 103 | AZ4: =IFERROR(__xludf.DUMMYFUNCTION("""COMPUTED_VALUE"""),111.0) -> 111 | BA4: =IFERROR(__xludf.DUMMYFUNCTION("""COMPUTED_VALUE"""),119.88000000000001) -> 119.88 | BB4: =IFERROR(__xludf.DUMMYFUNCTION("""COMPUTED_VALUE"""),119.88000000000001) -> 119.88 | BC4: =IFERROR(__xludf.DUMMYFUNCTION("""COMPUTED_VALUE"""),135.0) -> 135 | BD4: =IFERROR(__xludf.DUMMYFUNCTION("""COMPUTED_VALUE"""),142.0) -> 142 | BE4: =IFERROR(__xludf.DUMMYFUNCTION("""COMPUTED_VALUE"""),22.72) -> 22.72 | BF4: =IFERROR(__xludf.DUMMYFUNCTION("""COMPUTED_VALUE"""),164.72) -> 164.72 | BG4: =IFERROR(__xludf.DUMMYFUNCTION("""COMPUTED_VALUE"""),0.05185185185185185) -> 0.051851852 | BH4: =IFERROR(__xludf.DUMMYFUNCTION("""COMPUTED_VALUE"""),134.9) -> 134.9 | BI4: =IFERROR(__xludf.DUMMYFUNCTION("""COMPUTED_VALUE"""),21.584) -> 21.584 | BJ4: =IFERROR(__xludf.DUMMYFUNCTION("""COMPUTED_VALUE"""),156.484) -> 156.484 | BK4: =IFERROR(__xludf.DUMMYFUNCTION("""COMPUTED_VALUE"""),127.8) -> 127.8 | BL4: =IFERROR(__xludf.DUMMYFUNCTION("""COMPUTED_VALUE"""),20.448) -> 20.448 | BM4: =IFERROR(__xludf.DUMMYFUNCTION("""COMPUTED_VALUE"""),148.248) -> 148.248 | BN4: =IFERROR(__xludf.DUMMYFUNCTION("""COMPUTED_VALUE"""),120.7) -> 120.7 | BO4: =IFERROR(__xludf.DUMMYFUNCTION("""COMPUTED_VALUE"""),19.312) -> 19.312 | BP4: =IFERROR(__xludf.DUMMYFUNCTION("""COMPUTED_VALUE"""),140.012) -> 140.012 | BQ4: =IFERROR(__xludf.DUMMYFUNCTION("""COMPUTED_VALUE"""),120.7) -> 120.7 | BR4: =IFERROR(__xludf.DUMMYFUNCTION("""COMPUTED_VALUE"""),19.312) -> 19.312 | BS4: =IFERROR(__xludf.DUMMYFUNCTION("""COMPUTED_VALUE"""),140.012) -> 140.012 | BT4: =IFERROR(__xludf.DUMMYFUNCTION("""COMPUTED_VALUE"""),120.7) -> 120.7 | BU4: =IFERROR(__xludf.DUMMYFUNCTION("""COMPUTED_VALUE"""),19.312) -> 19.312 | BV4: =IFERROR(__xludf.DUMMYFUNCTION("""COMPUTED_VALUE"""),140.012) -> 140.012
A5: 1 | C5: C | D5: AC02 | E5: PZA | F5: REF | G5: ACEITE SAE BARDAHL 40 | H5: =G5 -> ACEITE SAE BARDAHL 40 | I5: =IF(D5="","",LEN(H5)) -> 21 | N5: 100 | O5: 108 | P5: 134.78 | Q5: 134.78 | R5: 130 | S5: 137 | T5: =S5*0.16 -> 21.92 | U5: =S5+T5 -> 158.92 | V5: =(S5-R5)/R5 -> 0.053846154 | W5: =(IF(B5="",(S5*(1-$W$1)),(IF(B5=1,(S5*(1-$W$1)),(IF(B5=2,(S5*(1-$W$1)),(IF(B5=3,(S5*(1-$W$1)),(IF(B5=4,(S5*(1)))))))))))) -> 130.15 | X5: =W5*0.16 -> 20.824 | Y5: =W5+X5 -> 150.974 | Z5: =(IF(B5="",(S5*(1-$Z$1)),(IF(B5=1,(S5*(1-$Z$1)),(IF(B5=2,(S5*(1-$Z$1)),(IF(B5=3,(S5*(1-$Z$1)),(IF(B5=4,(S5*(1)))))))))))) -> 123.3 | AA5: =Z5*0.16 -> 19.728 | AB5: =Z5+AA5 -> 143.028 | AC5: =(IF(B5="",(S5*(1-$AC$1)),(IF(B5=1,(S5*(1-$AC$1)),(IF(B5=2,(S5*(1-0.15)),(IF(B5=3,(S5*(1-0.1)),(IF(B5=4,(S5*(1)))))))))))) -> 116.45 | AD5: =AC5*0.16 -> 18.632 | AE5: =AC5+AD5 -> 135.082 | AF5: =(IF(B5="",(S5*(1-$AF$1)),(IF(B5=1,(S5*(1-$AF$1)),(IF(B5=2,(S5*(1-0.15)),(IF(B5=3,(S5*(1-0.1)),(IF(B5=4,(S5*(1)))))))))))) -> 113.71 | AG5: =AF5*0.16 -> 18.1936 | AH5: =AF5+AG5 -> 131.9036 | AI5: =(IF(B5="",(S5*(1-$AI$1)),(IF(B5=1,(S5*(1-$AI$1)),(IF(B5=2,(S5*(1-0.15)),(IF(B5=3,(S5*(1-0.1)),(IF(B5=4,(S5*(1)))))))))))) -> 109.6 | AJ5: =AI5*0.16 -> 17.536 | AK5: =AI5+AJ5 -> 127.136 | AL5: =IFERROR(__xludf.DUMMYFUNCTION("""COMPUTED_VALUE"""),1.0) -> 1 | AM5: =IFERROR(__xludf.DUMMYFUNCTION("""COMPUTED_VALUE"""),2.0) -> 2 | AN5: =IFERROR(__xludf.DUMMYFUNCTION("""COMPUTED_VALUE""")," C") -> C | AO5: =IFERROR(__xludf.DUMMYFUNCTION("""COMPUTED_VALUE""")," AE02") -> AE02 | AP5: =IFERROR(__xludf.DUMMYFUNCTION("""COMPUTED_VALUE""")," PZA") -> PZA | AQ5: =IFERROR(__xludf.DUMMYFUNCTION("""COMPUTED_VALUE""")," REF") -> REF | AR5: =IFERROR(__xludf.DUMMYFUNCTION("""COMPUTED_VALUE""")," ACEITERA DE PIPETA FLEXIBLE 500 ML. TRUPER") -> ACEITERA DE PIPETA FLEXIBLE 500 ML. TRUPER | AS5: =IFERROR(__xludf.DUMMYFUNCTION("""COMPUTED_VALUE""")," ACEITERA PIPETA FLEXIBLE 500 ML TRUPER") -> ACEITERA PIPETA FLEXIBLE 500 ML TRUPER | AT5: =IFERROR(__xludf.DUMMYFUNCTION("""COMPUTED_VALUE"""),38.0) -> 38 | AY5: =IFERROR(__xludf.DUMMYFUNCTION("""COMPUTED_VALUE"""),119.0) -> 119 | AZ5: =IFERROR(__xludf.DUMMYFUNCTION("""COMPUTED_VALUE"""),128.0) -> 128 | BA5: =IFERROR(__xludf.DUMMYFUNCTION("""COMPUTED_VALUE"""),138.24) -> 138.24 | BB5: =IFERROR(__xludf.DUMMYFUNCTION("""COMPUTED_VALUE"""),138.24) -> 138.24 | BC5: =IFERROR(__xludf.DUMMYFUNCTION("""COMPUTED_VALUE"""),155.0) -> 155 | BD5: =IFERROR(__xludf.DUMMYFUNCTION("""COMPUTED_VALUE"""),163.0) -> 163 | BE5: =IFERROR(__xludf.DUMMYFUNCTION("""COMPUTED_VALUE"""),26.080000000000002) -> 26.08 | BF5: =IFERROR(__xludf.DUMMYFUNCTION("""COMPUTED_VALUE"""),189.08) -> 189.08 | BG5: =IFERROR(__xludf.DUMMYFUNCTION("""COMPUTED_VALUE"""),0.05161290322580645) -> 0.051612903 | BH5: =IFERROR(__xludf.DUMMYFUNCTION("""COMPUTED_VALUE"""),154.85) -> 154.85 | BI5: =IFERROR(__xludf.DUMMYFUNCTION("""COMPUTED_VALUE"""),24.776) -> 24.776 | BJ5: =IFERROR(__xludf.DUMMYFUNCTION("""COMPUTED_VALUE"""),179.626) -> 179.626 | BK5: =IFERROR(__xludf.DUMMYFUNCTION("""COMPUTED_VALUE"""),146.70000000000002) -> 146.7 | BL5: =IFERROR(__xludf.DUMMYFUNCTION("""COMPUTED_VALUE"""),23.472000000000005) -> 23.472 | BM5: =IFERROR(__xludf.DUMMYFUNCTION("""COMPUTED_VALUE"""),170.17200000000003) -> 170.172 | BN5: =IFERROR(__xludf.DUMMYFUNCTION("""COMPUTED_VALUE"""),138.54999999999998) -> 138.55 | BO5: =IFERROR(__xludf.DUMMYFUNCTION("""COMPUTED_VALUE"""),22.168) -> 22.168 | BP5: =IFERROR(__xludf.DUMMYFUNCTION("""COMPUTED_VALUE"""),160.718) -> 160.718 | BQ5: =IFERROR(__xludf.DUMMYFUNCTION("""COMPUTED_VALUE"""),138.54999999999998) -> 138.55 | BR5: =IFERROR(__xludf.DUMMYFUNCTION("""COMPUTED_VALUE"""),22.168) -> 22.168 | BS5: =IFERROR(__xludf.DUMMYFUNCTION("""COMPUTED_VALUE"""),160.718) -> 160.718 | BT5: =IFERROR(__xludf.DUMMYFUNCTION("""COMPUTED_VALUE"""),138.54999999999998) -> 138.55 | BU5: =IFERROR(__xludf.DUMMYFUNCTION("""COMPUTED_VALUE"""),22.168) -> 22.168 | BV5: =IFERROR(__xludf.DUMMYFUNCTION("""COMPUTED_VALUE"""),160.718) -> 160.718
A6: 1 | B6: 2 | C6: C | D6: AE01 | E6: PZA | F6: REF | G6: ACEITERA DE PIPETA FLEXIBLE 300 ML. TRUPER | H6: ACEITERA PIPETA FLEXIBLE 300 ML TRUPER | I6: =IF(D6="","",LEN(H6)) -> 38 | N6: 103 | O6: 111 | P6: 119.88 | Q6: 119.88 | R6: 135 | S6: 142 | T6: =S6*0.16 -> 22.72 | U6: =S6+T6 -> 164.72 | V6: =(S6-R6)/R6 -> 0.051851852 | W6: =(IF(B6="",(S6*(1-$W$1)),(IF(B6=1,(S6*(1-$W$1)),(IF(B6=2,(S6*(1-$W$1)),(IF(B6=3,(S6*(1-$W$1)),(IF(B6=4,(S6*(1)))))))))))) -> 134.9 | X6: =W6*0.16 -> 21.584 | Y6: =W6+X6 -> 156.484 | Z6: =(IF(B6="",(S6*(1-$Z$1)),(IF(B6=1,(S6*(1-$Z$1)),(IF(B6=2,(S6*(1-$Z$1)),(IF(B6=3,(S6*(1-$Z$1)),(IF(B6=4,(S6*(1)))))))))))) -> 127.8 | AA6: =Z6*0.16 -> 20.448 | AB6: =Z6+AA6 -> 148.248 | AC6: =(IF(B6="",(S6*(1-$AC$1)),(IF(B6=1,(S6*(1-$AC$1)),(IF(B6=2,(S6*(1-0.15)),(IF(B6=3,(S6*(1-0.1)),(IF(B6=4,(S6*(1)))))))))))) -> 120.7 | AD6: =AC6*0.16 -> 19.312 | AE6: =AC6+AD6 -> 140.012 | AF6: =(IF(B6="",(S6*(1-$AF$1)),(IF(B6=1,(S6*(1-$AF$1)),(IF(B6=2,(S6*(1-0.15)),(IF(B6=3,(S6*(1-0.1)),(IF(B6=4,(S6*(1)))))))))))) -> 120.7 | AG6: =AF6*0.16 -> 19.312 | AH6: =AF6+AG6 -> 140.012 | AI6: =(IF(B6="",(S6*(1-$AI$1)),(IF(B6=1,(S6*(1-$AI$1)),(IF(B6=2,(S6*(1-0.15)),(IF(B6=3,(S6*(1-0.1)),(IF(B6=4,(S6*(1)))))))))))) -> 120.7 | AJ6: =AI6*0.16 -> 19.312 | AK6: =AI6+AJ6 -> 140.012 | AL6: =IFERROR(__xludf.DUMMYFUNCTION("""COMPUTED_VALUE"""),1.0) -> 1 | AN6: =IFERROR(__xludf.DUMMYFUNCTION("""COMPUTED_VALUE""")," P") -> P | AO6: =IFERROR(__xludf.DUMMYFUNCTION("""COMPUTED_VALUE""")," AM10") -> AM10 | AP6: =IFERROR(__xludf.DUMMYFUNCTION("""COMPUTED_VALUE""")," PZA") -> PZA | AQ6: =IFERROR(__xludf.DUMMYFUNCTION("""COMPUTED_VALUE""")," REF") -> REF | AR6: =IFERROR(__xludf.DUMMYFUNCTION("""COMPUTED_VALUE""")," ACOMODADOR DE TORTILLAS CUADRUPLEX") -> ACOMODADOR DE TORTILLAS CUADRUPLEX | AS6: =IFERROR(__xludf.DUMMYFUNCTION("""COMPUTED_VALUE""")," ACOMODADOR DE TORTILLAS CUADRUPLEX") -> ACOMODADOR DE TORTILLAS CUADRUPLEX | AT6: =IFERROR(__xludf.DUMMYFUNCTION("""COMPUTED_VALUE"""),34.0) -> 34 | AY6: =IFERROR(__xludf.DUMMYFUNCTION("""COMPUTED_VALUE"""),4097.0) -> 4097 | AZ6: =IFERROR(__xludf.DUMMYFUNCTION("""COMPUTED_VALUE"""),4424.0) -> 4424 | BA6: =IFERROR(__xludf.DUMMYFUNCTION("""COMPUTED_VALUE"""),4777.92) -> 4777.92 | BB6: =IFERROR(__xludf.DUMMYFUNCTION("""COMPUTED_VALUE"""),4777.92) -> 4777.92 | BC6: =IFERROR(__xludf.DUMMYFUNCTION("""COMPUTED_VALUE"""),5319.0) -> 5319 | BD6: =IFERROR(__xludf.DUMMYFUNCTION("""COMPUTED_VALUE"""),5585.0) -> 5585 | BE6: =IFERROR(__xludf.DUMMYFUNCTION("""COMPUTED_VALUE"""),893.6) -> 893.6 | BF6: =IFERROR(__xludf.DUMMYFUNCTION("""COMPUTED_VALUE"""),6478.6) -> 6478.6 | BG6: =IFERROR(__xludf.DUMMYFUNCTION("""COMPUTED_VALUE"""),0.05000940026320737) -> 0.0500094 | BH6: =IFERROR(__xludf.DUMMYFUNCTION("""COMPUTED_VALUE"""),5305.75) -> 5305.75 | BI6: =IFERROR(__xludf.DUMMYFUNCTION("""COMPUTED_VALUE"""),848.9200000000001) -> 848.92 | BJ6: =IFERROR(__xludf.DUMMYFUNCTION("""COMPUTED_VALUE"""),6154.67) -> 6154.67 | BK6: =IFERROR(__xludf.DUMMYFUNCTION("""COMPUTED_VALUE"""),5026.5) -> 5026.5 | BL6: =IFERROR(__xludf.DUMMYFUNCTION("""COMPUTED_VALUE"""),804.24) -> 804.24 | BM6: =IFERROR(__xludf.DUMMYFUNCTION("""COMPUTED_VALUE"""),5830.74) -> 5830.74 | BN6: =IFERROR(__xludf.DUMMYFUNCTION("""COMPUTED_VALUE"""),4747.25) -> 4747.25 | BO6: =IFERROR(__xludf.DUMMYFUNCTION("""COMPUTED_VALUE"""),759.5600000000001) -> 759.56 | BP6: =IFERROR(__xludf.DUMMYFUNCTION("""COMPUTED_VALUE"""),5506.81) -> 5506.81 | BQ6: =IFERROR(__xludf.DUMMYFUNCTION("""COMPUTED_VALUE"""),4635.55) -> 4635.55 | BR6: =IFERROR(__xludf.DUMMYFUNCTION("""COMPUTED_VALUE"""),741.688) -> 741.688 | BS6: =IFERROR(__xludf.DUMMYFUNCTION("""COMPUTED_VALUE"""),5377.238) -> 5377.238 | BT6: =IFERROR(__xludf.DUMMYFUNCTION("""COMPUTED_VALUE"""),4468.0) -> 4468 | BU6: =IFERROR(__xludf.DUMMYFUNCTION("""COMPUTED_VALUE"""),714.88) -> 714.88 | BV6: =IFERROR(__xludf.DUMMYFUNCTION("""COMPUTED_VALUE"""),5182.88) -> 5182.88
A7: 1 | B7: 2 | C7: C | D7: AE02 | E7: PZA | F7: REF | G7: ACEITERA DE PIPETA FLEXIBLE 500 ML. TRUPER | H7: ACEITERA PIPETA FLEXIBLE 500 ML TRUPER | I7: =IF(D7="","",LEN(H7)) -> 38 | N7: 119 | O7: 128 | P7: 138.24 | Q7: 138.24 | R7: 155 | S7: 163 | T7: =S7*0.16 -> 26.08 | U7: =S7+T7 -> 189.08 | V7: =(S7-R7)/R7 -> 0.051612903 | W7: =(IF(B7="",(S7*(1-$W$1)),(IF(B7=1,(S7*(1-$W$1)),(IF(B7=2,(S7*(1-$W$1)),(IF(B7=3,(S7*(1-$W$1)),(IF(B7=4,(S7*(1)))))))))))) -> 154.85 | X7: =W7*0.16 -> 24.776 | Y7: =W7+X7 -> 179.626 | Z7: =(IF(B7="",(S7*(1-$Z$1)),(IF(B7=1,(S7*(1-$Z$1)),(IF(B7=2,(S7*(1-$Z$1)),(IF(B7=3,(S7*(1-$Z$1)),(IF(B7=4,(S7*(1)))))))))))) -> 146.7 | AA7: =Z7*0.16 -> 23.472 | AB7: =Z7+AA7 -> 170.172 | AC7: =(IF(B7="",(S7*(1-$AC$1)),(IF(B7=1,(S7*(1-$AC$1)),(IF(B7=2,(S7*(1-0.15)),(IF(B7=3,(S7*(1-0.1)),(IF(B7=4,(S7*(1)))))))))))) -> 138.55 | AD7: =AC7*0.16 -> 22.168 | AE7: =AC7+AD7 -> 160.718 | AF7: =(IF(B7="",(S7*(1-$AF$1)),(IF(B7=1,(S7*(1-$AF$1)),(IF(B7=2,(S7*(1-0.15)),(IF(B7=3,(S7*(1-0.1)),(IF(B7=4,(S7*(1)))))))))))) -> 138.55 | AG7: =AF7*0.16 -> 22.168 | AH7: =AF7+AG7 -> 160.718 | AI7: =(IF(B7="",(S7*(1-$AI$1)),(IF(B7=1,(S7*(1-$AI$1)),(IF(B7=2,(S7*(1-0.15)),(IF(B7=3,(S7*(1-0.1)),(IF(B7=4,(S7*(1)))))))))))) -> 138.55 | AJ7: =AI7*0.16 -> 22.168 | AK7: =AI7+AJ7 -> 160.718 | AL7: =IFERROR(__xludf.DUMMYFUNCTION("""COMPUTED_VALUE"""),1.0) -> 1 | AN7: =IFERROR(__xludf.DUMMYFUNCTION("""COMPUTED_VALUE""")," P") -> P | AO7: =IFERROR(__xludf.DUMMYFUNCTION("""COMPUTED_VALUE""")," AM01") -> AM01 | AP7: =IFERROR(__xludf.DUMMYFUNCTION("""COMPUTED_VALUE""")," PZA") -> PZA | AQ7: =IFERROR(__xludf.DUMMYFUNCTION("""COMPUTED_VALUE""")," REF") -> REF | AR7: =IFERROR(__xludf.DUMMYFUNCTION("""COMPUTED_VALUE""")," ACOMODADOR DE TORTILLAS ESTÁNDAR (10-17 CM.)") -> ACOMODADOR DE TORTILLAS ESTÁNDAR (10-17 CM.) | AS7: =IFERROR(__xludf.DUMMYFUNCTION("""COMPUTED_VALUE""")," ACOMODADOR DE TORTILLAS STD 10-17 CM") -> ACOMODADOR DE TORTILLAS STD 10-17 CM | AT7: =IFERROR(__xludf.DUMMYFUNCTION("""COMPUTED_VALUE"""),36.0) -> 36 | AY7: =IFERROR(__xludf.DUMMYFUNCTION("""COMPUTED_VALUE"""),780.0) -> 780 | AZ7: =IFERROR(__xludf.DUMMYFUNCTION("""COMPUTED_VALUE"""),842.0) -> 842 | BA7: =IFERROR(__xludf.DUMMYFUNCTION("""COMPUTED_VALUE"""),909.36) -> 909.36 | BB7: =IFERROR(__xludf.DUMMYFUNCTION("""COMPUTED_VALUE"""),909.36) -> 909.36 | BC7: =IFERROR(__xludf.DUMMYFUNCTION("""COMPUTED_VALUE"""),1013.0) -> 1013 | BD7: =IFERROR(__xludf.DUMMYFUNCTION("""COMPUTED_VALUE"""),1064.0) -> 1064 | BE7: =IFERROR(__xludf.DUMMYFUNCTION("""COMPUTED_VALUE"""),170.24) -> 170.24 | BF7: =IFERROR(__xludf.DUMMYFUNCTION("""COMPUTED_VALUE"""),1234.24) -> 1234.24 | BG7: =IFERROR(__xludf.DUMMYFUNCTION("""COMPUTED_VALUE"""),0.050345508390918066) -> 0.050345508 | BH7: =IFERROR(__xludf.DUMMYFUNCTION("""COMPUTED_VALUE"""),1010.8) -> 1010.8 | BI7: =IFERROR(__xludf.DUMMYFUNCTION("""COMPUTED_VALUE"""),161.728) -> 161.728 | BJ7: =IFERROR(__xludf.DUMMYFUNCTION("""COMPUTED_VALUE"""),1172.528) -> 1172.528 | BK7: =IFERROR(__xludf.DUMMYFUNCTION("""COMPUTED_VALUE"""),957.6) -> 957.6 | BL7: =IFERROR(__xludf.DUMMYFUNCTION("""COMPUTED_VALUE"""),153.216) -> 153.216 | BM7: =IFERROR(__xludf.DUMMYFUNCTION("""COMPUTED_VALUE"""),1110.816) -> 1110.816 | BN7: =IFERROR(__xludf.DUMMYFUNCTION("""COMPUTED_VALUE"""),904.4) -> 904.4 | BO7: =IFERROR(__xludf.DUMMYFUNCTION("""COMPUTED_VALUE"""),144.704) -> 144.704 | BP7: =IFERROR(__xludf.DUMMYFUNCTION("""COMPUTED_VALUE"""),1049.104) -> 1049.104 | BQ7: =IFERROR(__xludf.DUMMYFUNCTION("""COMPUTED_VALUE"""),883.12) -> 883.12 | BR7: =IFERROR(__xludf.DUMMYFUNCTION("""COMPUTED_VALUE"""),141.2992) -> 141.2992 | BS7: =IFERROR(__xludf.DUMMYFUNCTION("""COMPUTED_VALUE"""),1024.4192) -> 1024.4192 | BT7: =IFERROR(__xludf.DUMMYFUNCTION("""COMPUTED_VALUE"""),851.2) -> 851.2 | BU7: =IFERROR(__xludf.DUMMYFUNCTION("""COMPUTED_VALUE"""),136.192) -> 136.192 | BV7: =IFERROR(__xludf.DUMMYFUNCTION("""COMPUTED_VALUE"""),987.392) -> 987.392
C8: P | D8: AM16 | E8: PZA | F8: REF | G8: ACOMODADOR MÁQUINA TVRD 15CM | H8: ACOMODADOR MAQUINA TVRD 15CM | I8: =IF(D8="","",LEN(H8)) -> 29 | N8: 2100 | O8: 2268 | P8: 2449.44 | Q8: 2449.44 | R8: 2572 | S8: 2701 | T8: =S8*0.16 -> 432.16 | U8: =S8+T8 -> 3133.16 | V8: =(S8-R8)/R8 -> 0.050155521 | W8: =(IF(B8="",(S8*(1-$W$1)),(IF(B8=1,(S8*(1-$W$1)),(IF(B8=2,(S8*(1-$W$1)),(IF(B8=3,(S8*(1-$W$1)),(IF(B8=4,(S8*(1)))))))))))) -> 2565.95 | X8: =W8*0.16 -> 410.552 | Y8: =W8+X8 -> 2976.502 | Z8: =(IF(B8="",(S8*(1-$Z$1)),(IF(B8=1,(S8*(1-$Z$1)),(IF(B8=2,(S8*(1-$Z$1)),(IF(B8=3,(S8*(1-$Z$1)),(IF(B8=4,(S8*(1)))))))))))) -> 2430.9 | AA8: =Z8*0.16 -> 388.944 | AB8: =Z8+AA8 -> 2819.844 | AC8: =(IF(B8="",(S8*(1-$AC$1)),(IF(B8=1,(S8*(1-$AC$1)),(IF(B8=2,(S8*(1-0.15)),(IF(B8=3,(S8*(1-0.1)),(IF(B8=4,(S8*(1)))))))))))) -> 2295.85 | AD8: =AC8*0.16 -> 367.336 | AE8: =AC8+AD8 -> 2663.186 | AF8: =(IF(B8="",(S8*(1-$AF$1)),(IF(B8=1,(S8*(1-$AF$1)),(IF(B8=2,(S8*(1-0.15)),(IF(B8=3,(S8*(1-0.1)),(IF(B8=4,(S8*(1)))))))))))) -> 2241.83 | AG8: =AF8*0.16 -> 358.6928 | AH8: =AF8+AG8 -> 2600.5228 | AI8: =(IF(B8="",(S8*(1-$AI$1)),(IF(B8=1,(S8*(1-$AI$1)),(IF(B8=2,(S8*(1-0.15)),(IF(B8=3,(S8*(1-0.1)),(IF(B8=4,(S8*(1)))))))))))) -> 2160.8 | AJ8: =AI8*0.16 -> 345.728 | AK8: =AI8+AJ8 -> 2506.528 | AL8: =IFERROR(__xludf.DUMMYFUNCTION("""COMPUTED_VALUE"""),1.0) -> 1 | AN8: =IFERROR(__xludf.DUMMYFUNCTION("""COMPUTED_VALUE""")," P") -> P | AO8: =IFERROR(__xludf.DUMMYFUNCTION("""COMPUTED_VALUE""")," AM02") -> AM02 | AP8: =IFERROR(__xludf.DUMMYFUNCTION("""COMPUTED_VALUE""")," PZA") -> PZA | AQ8: =IFERROR(__xludf.DUMMYFUNCTION("""COMPUTED_VALUE""")," REF") -> REF | AR8: =IFERROR(__xludf.DUMMYFUNCTION("""COMPUTED_VALUE""")," ACOMODADOR DE TORTILLAS TIPO PUEBLA ") -> ACOMODADOR DE TORTILLAS TIPO PUEBLA | AS8: =IFERROR(__xludf.DUMMYFUNCTION("""COMPUTED_VALUE""")," ACOMODADOR DE TORTILLAS TIPO PUEBLA ") -> ACOMODADOR DE TORTILLAS TIPO PUEBLA | AT8: =IFERROR(__xludf.DUMMYFUNCTION("""COMPUTED_VALUE"""),36.0) -> 36 | AY8: =IFERROR(__xludf.DUMMYFUNCTION("""COMPUTED_VALUE"""),898.0) -> 898 | AZ8: =IFERROR(__xludf.DUMMYFUNCTION("""COMPUTED_VALUE"""),969.0) -> 969 | BA8: =IFERROR(__xludf.DUMMYFUNCTION("""COMPUTED_VALUE"""),1046.52) -> 1046.52 | BB8: =IFERROR(__xludf.DUMMYFUNCTION("""COMPUTED_VALUE"""),1046.52) -> 1046.52 | BC8: =IFERROR(__xludf.DUMMYFUNCTION("""COMPUTED_VALUE"""),1166.0) -> 1166 | BD8: =IFERROR(__xludf.DUMMYFUNCTION("""COMPUTED_VALUE"""),1224.0) -> 1224 | BE8: =IFERROR(__xludf.DUMMYFUNCTION("""COMPUTED_VALUE"""),195.84) -> 195.84 | BF8: =IFERROR(__xludf.DUMMYFUNCTION("""COMPUTED_VALUE"""),1419.84) -> 1419.84 | BG8: =IFERROR(__xludf.DUMMYFUNCTION("""COMPUTED_VALUE"""),0.04974271012006861) -> 0.04974271 | BH8: =IFERROR(__xludf.DUMMYFUNCTION("""COMPUTED_VALUE"""),1162.8) -> 1162.8 | BI8: =IFERROR(__xludf.DUMMYFUNCTION("""COMPUTED_VALUE"""),186.048) -> 186.048 | BJ8: =IFERROR(__xludf.DUMMYFUNCTION("""COMPUTED_VALUE"""),1348.848) -> 1348.848 | BK8: =IFERROR(__xludf.DUMMYFUNCTION("""COMPUTED_VALUE"""),1101.6000000000001) -> 1101.6 | BL8: =IFERROR(__xludf.DUMMYFUNCTION("""COMPUTED_VALUE"""),176.25600000000003) -> 176.256 | BM8: =IFERROR(__xludf.DUMMYFUNCTION("""COMPUTED_VALUE"""),1277.8560000000002) -> 1277.856 | BN8: =IFERROR(__xludf.DUMMYFUNCTION("""COMPUTED_VALUE"""),1040.3999999999999) -> 1040.4 | BO8: =IFERROR(__xludf.DUMMYFUNCTION("""COMPUTED_VALUE"""),166.46399999999997) -> 166.464 | BP8: =IFERROR(__xludf.DUMMYFUNCTION("""COMPUTED_VALUE"""),1206.8639999999998) -> 1206.864 | BQ8: =IFERROR(__xludf.DUMMYFUNCTION("""COMPUTED_VALUE"""),1015.92) -> 1015.92 | BR8: =IFERROR(__xludf.DUMMYFUNCTION("""COMPUTED_VALUE"""),162.5472) -> 162.5472 | BS8: =IFERROR(__xludf.DUMMYFUNCTION("""COMPUTED_VALUE"""),1178.4672) -> 1178.4672 | BT8: =IFERROR(__xludf.DUMMYFUNCTION("""COMPUTED_VALUE"""),979.2) -> 979.2 | BU8: =IFERROR(__xludf.DUMMYFUNCTION("""COMPUTED_VALUE"""),156.672) -> 156.672 | BV8: =IFERROR(__xludf.DUMMYFUNCTION("""COMPUTED_VALUE"""),1135.872) -> 1135.872
C9: P | D9: AM17 | E9: PZA | F9: REF | G9: ACOMODADOR MÁQUINA TVRD 16CM | H9: ACOMODADOR MAQUINA TVRD 16CM | I9: =IF(D9="","",LEN(H9)) -> 29 | N9: 2100 | O9: 2268 | P9: 2449.44 | Q9: 2449.44 | R9: 2572 | S9: 2701 | T9: =S9*0.16 -> 432.16 | U9: =S9+T9 -> 3133.16 | V9: =(S9-R9)/R9 -> 0.050155521 | W9: =(IF(B9="",(S9*(1-$W$1)),(IF(B9=1,(S9*(1-$W$1)),(IF(B9=2,(S9*(1-$W$1)),(IF(B9=3,(S9*(1-$W$1)),(IF(B9=4,(S9*(1)))))))))))) -> 2565.95 | X9: =W9*0.16 -> 410.552 | Y9: =W9+X9 -> 2976.502 | Z9: =(IF(B9="",(S9*(1-$Z$1)),(IF(B9=1,(S9*(1-$Z$1)),(IF(B9=2,(S9*(1-$Z$1)),(IF(B9=3,(S9*(1-$Z$1)),(IF(B9=4,(S9*(1)))))))))))) -> 2430.9 | AA9: =Z9*0.16 -> 388.944 | AB9: =Z9+AA9 -> 2819.844 | AC9: =(IF(B9="",(S9*(1-$AC$1)),(IF(B9=1,(S9*(1-$AC$1)),(IF(B9=2,(S9*(1-0.15)),(IF(B9=3,(S9*(1-0.1)),(IF(B9=4,(S9*(1)))))))))))) -> 2295.85 | AD9: =AC9*0.16 -> 367.336 | AE9: =AC9+AD9 -> 2663.186 | AF9: =(IF(B9="",(S9*(1-$AF$1)),(IF(B9=1,(S9*(1-$AF$1)),(IF(B9=2,(S9*(1-0.15)),(IF(B9=3,(S9*(1-0.1)),(IF(B9=4,(S9*(1)))))))))))) -> 2241.83 | AG9: =AF9*0.16 -> 358.6928 | AH9: =AF9+AG9 -> 2600.5228 | AI9: =(IF(B9="",(S9*(1-$AI$1)),(IF(B9=1,(S9*(1-$AI$1)),(IF(B9=2,(S9*(1-0.15)),(IF(B9=3,(S9*(1-0.1)),(IF(B9=4,(S9*(1)))))))))))) -> 2160.8 | AJ9: =AI9*0.16 -> 345.728 | AK9: =AI9+AJ9 -> 2506.528 | AL9: =IFERROR(__xludf.DUMMYFUNCTION("""COMPUTED_VALUE"""),1.0) -> 1 | AN9: =IFERROR(__xludf.DUMMYFUNCTION("""COMPUTED_VALUE""")," P") -> P | AO9: =IFERROR(__xludf.DUMMYFUNCTION("""COMPUTED_VALUE""")," AM18") -> AM18 | AP9: =IFERROR(__xludf.DUMMYFUNCTION("""COMPUTED_VALUE""")," JGO") -> JGO | AQ9: =IFERROR(__xludf.DUMMYFUNCTION("""COMPUTED_VALUE""")," REF") -> REF | AR9: =IFERROR(__xludf.DUMMYFUNCTION("""COMPUTED_VALUE""")," ACOMODADOR DE TORTILLAS TIPO PUEBLA CON TIRANTES (18-22 CM.)") -> ACOMODADOR DE TORTILLAS TIPO PUEBLA CON TIRANTES (18-22 CM.) | AS9: =IFERROR(__xludf.DUMMYFUNCTION("""COMPUTED_VALUE""")," ACOMODADOR TORT. T/PUE C/TIRANT 18-22 CM") -> ACOMODADOR TORT. T/PUE C/TIRANT 18-22 CM | AT9: =IFERROR(__xludf.DUMMYFUNCTION("""COMPUTED_VALUE"""),40.0) -> 40 | AY9: =IFERROR(__xludf.DUMMYFUNCTION("""COMPUTED_VALUE"""),1026.0) -> 1026 | AZ9: =IFERROR(__xludf.DUMMYFUNCTION("""COMPUTED_VALUE"""),1108.0) -> 1108 | BA9: =IFERROR(__xludf.DUMMYFUNCTION("""COMPUTED_VALUE"""),1196.64) -> 1196.64 | BB9: =IFERROR(__xludf.DUMMYFUNCTION("""COMPUTED_VALUE"""),1196.64) -> 1196.64 | BC9: =IFERROR(__xludf.DUMMYFUNCTION("""COMPUTED_VALUE"""),1257.0) -> 1257 | BD9: =IFERROR(__xludf.DUMMYFUNCTION("""COMPUTED_VALUE"""),1320.0) -> 1320 | BE9: =IFERROR(__xludf.DUMMYFUNCTION("""COMPUTED_VALUE"""),211.20000000000002) -> 211.2 | BF9: =IFERROR(__xludf.DUMMYFUNCTION("""COMPUTED_VALUE"""),1531.2) -> 1531.2 | BG9: =IFERROR(__xludf.DUMMYFUNCTION("""COMPUTED_VALUE"""),0.050119331742243436) -> 0.050119332 | BH9: =IFERROR(__xludf.DUMMYFUNCTION("""COMPUTED_VALUE"""),1254.0) -> 1254 | BI9: =IFERROR(__xludf.DUMMYFUNCTION("""COMPUTED_VALUE"""),200.64000000000001) -> 200.64 | BJ9: =IFERROR(__xludf.DUMMYFUNCTION("""COMPUTED_VALUE"""),1454.64) -> 1454.64 | BK9: =IFERROR(__xludf.DUMMYFUNCTION("""COMPUTED_VALUE"""),1188.0) -> 1188 | BL9: =IFERROR(__xludf.DUMMYFUNCTION("""COMPUTED_VALUE"""),190.08) -> 190.08 | BM9: =IFERROR(__xludf.DUMMYFUNCTION("""COMPUTED_VALUE"""),1378.08) -> 1378.08 | BN9: =IFERROR(__xludf.DUMMYFUNCTION("""COMPUTED_VALUE"""),1122.0) -> 1122 | BO9: =IFERROR(__xludf.DUMMYFUNCTION("""COMPUTED_VALUE"""),179.52) -> 179.52 | BP9: =IFERROR(__xludf.DUMMYFUNCTION("""COMPUTED_VALUE"""),1301.52) -> 1301.52 | BQ9: =IFERROR(__xludf.DUMMYFUNCTION("""COMPUTED_VALUE"""),1095.6) -> 1095.6 | BR9: =IFERROR(__xludf.DUMMYFUNCTION("""COMPUTED_VALUE"""),175.296) -> 175.296 | BS9: =IFERROR(__xludf.DUMMYFUNCTION("""COMPUTED_VALUE"""),1270.896) -> 1270.896 | BT9: =IFERROR(__xludf.DUMMYFUNCTION("""COMPUTED_VALUE"""),1056.0) -> 1056 | BU9: =IFERROR(__xludf.DUMMYFUNCTION("""COMPUTED_VALUE"""),168.96) -> 168.96 | BV9: =IFERROR(__xludf.DUMMYFUNCTION("""COMPUTED_VALUE"""),1224.96) -> 1224.96
B10: 3 | C10: E | D10: AM07 | E10: PZA | F10: TNO | G10: ACOMODADOR DE TORTILLAS AUTOMÁTICO DÚPLEX | I10: =IF(D10="","",LEN(H10)) -> 0 | O10: 17667 | P10: 19080.36 | Q10: 19080.36 | R10: 21036 | S10: 22088 | T10: =S10*0.16 -> 3534.08 | U10: =S10+T10 -> 25622.08 | V10: =(S10-R10)/R10 -> 0.050009508 | W10: =(IF(B10="",(S10*(1-$W$1)),(IF(B10=1,(S10*(1-$W$1)),(IF(B10=2,(S10*(1-$W$1)),(IF(B10=3,(S10*(1-$W$1)),(IF(B10=4,(S10*(1)))))))))))) -> 20983.6 | X10: =W10*0.16 -> 3357.376 | Y10: =W10+X10 -> 24340.976 | Z10: =(IF(B10="",(S10*(1-$Z$1)),(IF(B10=1,(S10*(1-$Z$1)),(IF(B10=2,(S10*(1-$Z$1)),(IF(B10=3,(S10*(1-$Z$1)),(IF(B10=4,(S10*(1)))))))))))) -> 19879.2 | AA10: =Z10*0.16 -> 3180.672 | AB10: =Z10+AA10 -> 23059.872 | AC10: =(IF(B10="",(S10*(1-$AC$1)),(IF(B10=1,(S10*(1-$AC$1)),(IF(B10=2,(S10*(1-0.15)),(IF(B10=3,(S10*(1-0.1)),(IF(B10=4,(S10*(1)))))))))))) -> 19879.2 | AD10: =AC10*0.16 -> 3180.672 | AE10: =AC10+AD10 -> 23059.872 | AF10: =(IF(B10="",(S10*(1-$AF$1)),(IF(B10=1,(S10*(1-$AF$1)),(IF(B10=2,(S10*(1-0.15)),(IF(B10=3,(S10*(1-0.1)),(IF(B10=4,(S10*(1)))))))))))) -> 19879.2 | AG10: =AF10*0.16 -> 3180.672 | AH10: =AF10+AG10 -> 23059.872 | AI10: =(IF(B10="",(S10*(1-$AI$1)),(IF(B10=1,(S10*(1-$AI$1)),(IF(B10=2,(S10*(1-0.15)),(IF(B10=3,(S10*(1-0.1)),(IF(B10=4,(S10*(1)))))))))))) -> 19879.2 | AJ10: =AI10*0.16 -> 3180.672 | AK10: =AI10+AJ10 -> 23059.872 | AL10: =IFERROR(__xludf.DUMMYFUNCTION("""COMPUTED_VALUE"""),1.0) -> 1 | AN10: =IFERROR(__xludf.DUMMYFUNCTION("""COMPUTED_VALUE""")," C") -> C | AO10: =IFERROR(__xludf.DUMMYFUNCTION("""COMPUTED_VALUE""")," RL15") -> RL15 | AP10: =IFERROR(__xludf.DUMMYFUNCTION("""COMPUTED_VALUE""")," PZA") -> PZA | AQ10: =IFERROR(__xludf.DUMMYFUNCTION("""COMPUTED_VALUE""")," REF") -> REF | AR10: =IFERROR(__xludf.DUMMYFUNCTION("""COMPUTED_VALUE""")," ALAMBRE DESPEGADOR 15 GR") -> ALAMBRE DESPEGADOR 15 GR | AS10: =IFERROR(__xludf.DUMMYFUNCTION("""COMPUTED_VALUE""")," ALAMBRE DESPEGADOR 15 GR") -> ALAMBRE DESPEGADOR 15 GR | AT10: =IFERROR(__xludf.DUMMYFUNCTION("""COMPUTED_VALUE"""),24.0) -> 24 | BC10: =IFERROR(__xludf.DUMMYFUNCTION("""COMPUTED_VALUE"""),42.0) -> 42 | BD10: =IFERROR(__xludf.DUMMYFUNCTION("""COMPUTED_VALUE"""),44.0) -> 44 | BE10: =IFERROR(__xludf.DUMMYFUNCTION("""COMPUTED_VALUE"""),7.04) -> 7.04 | BF10: =IFERROR(__xludf.DUMMYFUNCTION("""COMPUTED_VALUE"""),51.04) -> 51.04 | BG10: =IFERROR(__xludf.DUMMYFUNCTION("""COMPUTED_VALUE"""),0.047619047619047616) -> 0.047619048 | BH10: =IFERROR(__xludf.DUMMYFUNCTION("""COMPUTED_VALUE"""),41.8) -> 41.8 | BI10: =IFERROR(__xludf.DUMMYFUNCTION("""COMPUTED_VALUE"""),6.688) -> 6.688 | BJ10: =IFERROR(__xludf.DUMMYFUNCTION("""COMPUTED_VALUE"""),48.488) -> 48.488 | BK10: =IFERROR(__xludf.DUMMYFUNCTION("""COMPUTED_VALUE"""),39.6) -> 39.6 | BL10: =IFERROR(__xludf.DUMMYFUNCTION("""COMPUTED_VALUE"""),6.336) -> 6.336 | BM10: =IFERROR(__xludf.DUMMYFUNCTION("""COMPUTED_VALUE"""),45.936) -> 45.936 | BN10: =IFERROR(__xludf.DUMMYFUNCTION("""COMPUTED_VALUE"""),37.4) -> 37.4 | BO10: =IFERROR(__xludf.DUMMYFUNCTION("""COMPUTED_VALUE"""),5.984) -> 5.984 | BP10: =IFERROR(__xludf.DUMMYFUNCTION("""COMPUTED_VALUE"""),43.384) -> 43.384 | BQ10: =IFERROR(__xludf.DUMMYFUNCTION("""COMPUTED_VALUE"""),36.519999999999996) -> 36.52 | BR10: =IFERROR(__xludf.DUMMYFUNCTION("""COMPUTED_VALUE"""),5.8431999999999995) -> 5.8432 | BS10: =IFERROR(__xludf.DUMMYFUNCTION("""COMPUTED_VALUE"""),42.36319999999999) -> 42.3632 | BT10: =IFERROR(__xludf.DUMMYFUNCTION("""COMPUTED_VALUE"""),35.2) -> 35.2
B11: 3 | C11: E | D11: AM05 | E11: PZA | F11: TNO | G11: ACOMODADOR DE TORTILLAS AUTOMÁTICO SENCILLO (15 y 16 CM) | I11: =IF(D11="","",LEN(H11)) -> 0 | O11: 7624 | P11: 8233.92 | Q11: 8233.92 | R11: 9079 | S11: 9533 | T11: =S11*0.16 -> 1525.28 | U11: =S11+T11 -> 11058.28 | V11: =(S11-R11)/R11 -> 0.050005507 | W11: =(IF(B11="",(S11*(1-$W$1)),(IF(B11=1,(S11*(1-$W$1)),(IF(B11=2,(S11*(1-$W$1)),(IF(B11=3,(S11*(1-$W$1)),(IF(B11=4,(S11*(1)))))))))))) -> 9056.35 | X11: =W11*0.16 -> 1449.016 | Y11: =W11+X11 -> 10505.366 | Z11: =(IF(B11="",(S11*(1-$Z$1)),(IF(B11=1,(S11*(1-$Z$1)),(IF(B11=2,(S11*(1-$Z$1)),(IF(B11=3,(S11*(1-$Z$1)),(IF(B11=4,(S11*(1)))))))))))) -> 8579.7 | AA11: =Z11*0.16 -> 1372.752 | AB11: =Z11+AA11 -> 9952.452 | AC11: =(IF(B11="",(S11*(1-$AC$1)),(IF(B11=1,(S11*(1-$AC$1)),(IF(B11=2,(S11*(1-0.15)),(IF(B11=3,(S11*(1-0.1)),(IF(B11=4,(S11*(1)))))))))))) -> 8579.7 | AD11: =AC11*0.16 -> 1372.752 | AE11: =AC11+AD11 -> 9952.452 | AF11: =(IF(B11="",(S11*(1-$AF$1)),(IF(B11=1,(S11*(1-$AF$1)),(IF(B11=2,(S11*(1-0.15)),(IF(B11=3,(S11*(1-0.1)),(IF(B11=4,(S11*(1)))))))))))) -> 8579.7 | AG11: =AF11*0.16 -> 1372.752 | AH11: =AF11+AG11 -> 9952.452 | AI11: =(IF(B11="",(S11*(1-$AI$1)),(IF(B11=1,(S11*(1-$AI$1)),(IF(B11=2,(S11*(1-0.15)),(IF(B11=3,(S11*(1-0.1)),(IF(B11=4,(S11*(1)))))))))))) -> 8579.7 | AJ11: =AI11*0.16 -> 1372.752 | AK11: =AI11+AJ11 -> 9952.452 | AL11: =IFERROR(__xludf.DUMMYFUNCTION("""COMPUTED_VALUE"""),1.0) -> 1 | AN11: =IFERROR(__xludf.DUMMYFUNCTION("""COMPUTED_VALUE""")," C") -> C | AO11: =IFERROR(__xludf.DUMMYFUNCTION("""COMPUTED_VALUE""")," RL90") -> RL90 | AP11: =IFERROR(__xludf.DUMMYFUNCTION("""COMPUTED_VALUE""")," PZA") -> PZA | AQ11: =IFERROR(__xludf.DUMMYFUNCTION("""COMPUTED_VALUE""")," REF") -> REF | AR11: =IFERROR(__xludf.DUMMYFUNCTION("""COMPUTED_VALUE""")," ALAMBRE DESPEGADOR 90 GR") -> ALAMBRE DESPEGADOR 90 GR | AS11: =IFERROR(__xludf.DUMMYFUNCTION("""COMPUTED_VALUE""")," ALAMBRE DESPEGADOR 90 GR") -> ALAMBRE DESPEGADOR 90 GR | AT11: =IFERROR(__xludf.DUMMYFUNCTION("""COMPUTED_VALUE"""),24.0) -> 24 | BC11: =IFERROR(__xludf.DUMMYFUNCTION("""COMPUTED_VALUE"""),250.0) -> 250 | BD11: =IFERROR(__xludf.DUMMYFUNCTION("""COMPUTED_VALUE"""),263.0) -> 263 | BE11: =IFERROR(__xludf.DUMMYFUNCTION("""COMPUTED_VALUE"""),42.08) -> 42.08 | BF11: =IFERROR(__xludf.DUMMYFUNCTION("""COMPUTED_VALUE"""),305.08) -> 305.08 | BG11: =IFERROR(__xludf.DUMMYFUNCTION("""COMPUTED_VALUE"""),0.052) -> 0.052 | BH11: =IFERROR(__xludf.DUMMYFUNCTION("""COMPUTED_VALUE"""),249.85) -> 249.85 | BI11: =IFERROR(__xludf.DUMMYFUNCTION("""COMPUTED_VALUE"""),39.976) -> 39.976 | BJ11: =IFERROR(__xludf.DUMMYFUNCTION("""COMPUTED_VALUE"""),289.826) -> 289.826 | BK11: =IFERROR(__xludf.DUMMYFUNCTION("""COMPUTED_VALUE"""),236.70000000000002) -> 236.7 | BL11: =IFERROR(__xludf.DUMMYFUNCTION("""COMPUTED_VALUE"""),37.87200000000001) -> 37.872 | BM11: =IFERROR(__xludf.DUMMYFUNCTION("""COMPUTED_VALUE"""),274.572) -> 274.572 | BN11: =IFERROR(__xludf.DUMMYFUNCTION("""COMPUTED_VALUE"""),223.54999999999998) -> 223.55 | BO11: =IFERROR(__xludf.DUMMYFUNCTION("""COMPUTED_VALUE"""),35.768) -> 35.768 | BP11: =IFERROR(__xludf.DUMMYFUNCTION("""COMPUTED_VALUE"""),259.318) -> 259.318 | BQ11: =IFERROR(__xludf.DUMMYFUNCTION("""COMPUTED_VALUE"""),218.29) -> 218.29 | BR11: =IFERROR(__xludf.DUMMYFUNCTION("""COMPUTED_VALUE"""),34.9264) -> 34.9264 | BS11: =IFERROR(__xludf.DUMMYFUNCTION("""COMPUTED_VALUE"""),253.2164) -> 253.2164 | BT11: =IFERROR(__xludf.DUMMYFUNCTION("""COMPUTED_VALUE"""),210.4) -> 210.4
B12: 3 | C12: E | D12: AM06 | E12: PZA | F12: TNO | G12: ACOMODADOR DE TORTILLAS AUTOMÁTICO SENCILLO TIPO PUEBLA (18, 19 y 20 cm) | I12: =IF(D12="","",LEN(H12)) -> 0 | O12: 9037 | P12: 9759.96 | Q12: 9759.96 | R12: 10761 | S12: 11299 | T12: =S12*0.16 -> 1807.84 | U12: =S12+T12 -> 13106.84 | V12: =(S12-R12)/R12 -> 0.049995354 | W12: =(IF(B12="",(S12*(1-$W$1)),(IF(B12=1,(S12*(1-$W$1)),(IF(B12=2,(S12*(1-$W$1)),(IF(B12=3,(S12*(1-$W$1)),(IF(B12=4,(S12*(1)))))))))))) -> 10734.05 | X12: =W12*0.16 -> 1717.448 | Y12: =W12+X12 -> 12451.498 | Z12: =(IF(B12="",(S12*(1-$Z$1)),(IF(B12=1,(S12*(1-$Z$1)),(IF(B12=2,(S12*(1-$Z$1)),(IF(B12=3,(S12*(1-$Z$1)),(IF(B12=4,(S12*(1)))))))))))) -> 10169.1 | AA12: =Z12*0.16 -> 1627.056 | AB12: =Z12+AA12 -> 11796.156 | AC12: =(IF(B12="",(S12*(1-$AC$1)),(IF(B12=1,(S12*(1-$AC$1)),(IF(B12=2,(S12*(1-0.15)),(IF(B12=3,(S12*(1-0.1)),(IF(B12=4,(S12*(1)))))))))))) -> 10169.1 | AD12: =AC12*0.16 -> 1627.056 | AE12: =AC12+AD12 -> 11796.156 | AF12: =(IF(B12="",(S12*(1-$AF$1)),(IF(B12=1,(S12*(1-$AF$1)),(IF(B12=2,(S12*(1-0.15)),(IF(B12=3,(S12*(1-0.1)),(IF(B12=4,(S12*(1)))))))))))) -> 10169.1 | AG12: =AF12*0.16 -> 1627.056 | AH12: =AF12+AG12 -> 11796.156 | AI12: =(IF(B12="",(S12*(1-$AI$1)),(IF(B12=1,(S12*(1-$AI$1)),(IF(B12=2,(S12*(1-0.15)),(IF(B12=3,(S12*(1-0.1)),(IF(B12=4,(S12*(1)))))))))))) -> 10169.1 | AJ12: =AI12*0.16 -> 1627.056 | AK12: =AI12+AJ12 -> 11796.156 | AL12: =IFERROR(__xludf.DUMMYFUNCTION("""COMPUTED_VALUE"""),1.0) -> 1 | AN12: =IFERROR(__xludf.DUMMYFUNCTION("""COMPUTED_VALUE""")," C") -> C | AO12: =IFERROR(__xludf.DUMMYFUNCTION("""COMPUTED_VALUE""")," AN01") -> AN01 | AP12: =IFERROR(__xludf.DUMMYFUNCTION("""COMPUTED_VALUE""")," CUB") -> CUB | AQ12: =IFERROR(__xludf.DUMMYFUNCTION("""COMPUTED_VALUE""")," REF") -> REF | AR12: =IFERROR(__xludf.DUMMYFUNCTION("""COMPUTED_VALUE""")," ANTIADHERENTE ""A"" 19 LITROS") -> ANTIADHERENTE "A" 19 LITROS | AS12: =IFERROR(__xludf.DUMMYFUNCTION("""COMPUTED_VALUE""")," ANTIADHERENTE A 19 LITROS") -> ANTIADHERENTE A 19 LITROS | AT12: =IFERROR(__xludf.DUMMYFUNCTION("""COMPUTED_VALUE"""),25.0) -> 25 | AY12: =IFERROR(__xludf.DUMMYFUNCTION("""COMPUTED_VALUE"""),3537.0) -> 3537 | AZ12: =IFERROR(__xludf.DUMMYFUNCTION("""COMPUTED_VALUE"""),2554.0) -> 2554 | BA12: =IFERROR(__xludf.DUMMYFUNCTION("""COMPUTED_VALUE"""),2291.4) -> 2291.4 | BB12: =IFERROR(__xludf.DUMMYFUNCTION("""COMPUTED_VALUE"""),2291.4) -> 2291.4 | BC12: =IFERROR(__xludf.DUMMYFUNCTION("""COMPUTED_VALUE"""),2551.0) -> 2551 | BD12: =IFERROR(__xludf.DUMMYFUNCTION("""COMPUTED_VALUE"""),2679.0) -> 2679 | BE12: =IFERROR(__xludf.DUMMYFUNCTION("""COMPUTED_VALUE"""),428.64) -> 428.64 | BF12: =IFERROR(__xludf.DUMMYFUNCTION("""COMPUTED_VALUE"""),3107.64) -> 3107.64 | BG12: =IFERROR(__xludf.DUMMYFUNCTION("""COMPUTED_VALUE"""),0.05017640141121129) -> 0.050176401 | BH12: =IFERROR(__xludf.DUMMYFUNCTION("""COMPUTED_VALUE"""),2545.0499999999997) -> 2545.05 | BI12: =IFERROR(__xludf.DUMMYFUNCTION("""COMPUTED_VALUE"""),407.20799999999997) -> 407.208 | BJ12: =IFERROR(__xludf.DUMMYFUNCTION("""COMPUTED_VALUE"""),2952.258) -> 2952.258 | BK12: =IFERROR(__xludf.DUMMYFUNCTION("""COMPUTED_VALUE"""),2411.1) -> 2411.1 | BL12: =IFERROR(__xludf.DUMMYFUNCTION("""COMPUTED_VALUE"""),385.776) -> 385.776 | BM12: =IFERROR(__xludf.DUMMYFUNCTION("""COMPUTED_VALUE"""),2796.8759999999997) -> 2796.876 | BN12: =IFERROR(__xludf.DUMMYFUNCTION("""COMPUTED_VALUE"""),2277.15) -> 2277.15 | BO12: =IFERROR(__xludf.DUMMYFUNCTION("""COMPUTED_VALUE"""),364.344) -> 364.344 | BP12: =IFERROR(__xludf.DUMMYFUNCTION("""COMPUTED_VALUE"""),2641.494) -> 2641.494 | BQ12: =IFERROR(__xludf.DUMMYFUNCTION("""COMPUTED_VALUE"""),2223.5699999999997) -> 2223.57 | BR12: =IFERROR(__xludf.DUMMYFUNCTION("""COMPUTED_VALUE"""),355.77119999999996) -> 355.7712 | BS12: =IFERROR(__xludf.DUMMYFUNCTION("""COMPUTED_VALUE"""),2579.3412) -> 2579.3412 | BT12: =IFERROR(__xludf.DUMMYFUNCTION("""COMPUTED_VALUE"""),2143.2000000000003) -> 2143.2 | BU12: =IFERROR(__xludf.DUMMYFUNCTION("""COMPUTED_VALUE"""),342.91200000000003) -> 342.912 | BV12: =IFERROR(__xludf.DUMMYFUNCTION("""COMPUTED_VALUE"""),2486.112) -> 2486.112
C13: E | D13: AM03 | E13: PZA | F13: WAL | G13: ACOMODADOR DE TORTILLAS CON SOLERAS WALMART | I13: =IF(D13="","",LEN(H13)) -> 0 | O13: 1559.04 | P13: 1683.7632 | Q13: 1683.7632 | R13: 1769 | S13: 1857 | T13: =S13*0.16 -> 297.12 | U13: =S13+T13 -> 2154.12 | V13: =(S13-R13)/R13 -> 0.049745619 | W13: =(IF(B13="",(S13*(1-$W$1)),(IF(B13=1,(S13*(1-$W$1)),(IF(B13=2,(S13*(1-$W$1)),(IF(B13=3,(S13*(1-$W$1)),(IF(B13=4,(S13*(1)))))))))))) -> 1764.15 | X13: =W13*0.16 -> 282.264 | Y13: =W13+X13 -> 2046.414 | Z13: =(IF(B13="",(S13*(1-$Z$1)),(IF(B13=1,(S13*(1-$Z$1)),(IF(B13=2,(S13*(1-$Z$1)),(IF(B13=3,(S13*(1-$Z$1)),(IF(B13=4,(S13*(1)))))))))))) -> 1671.3 | AA13: =Z13*0.16 -> 267.408 | AB13: =Z13+AA13 -> 1938.708 | AC13: =(IF(B13="",(S13*(1-$AC$1)),(IF(B13=1,(S13*(1-$AC$1)),(IF(B13=2,(S13*(1-0.15)),(IF(B13=3,(S13*(1-0.1)),(IF(B13=4,(S13*(1)))))))))))) -> 1578.45 | AD13: =AC13*0.16 -> 252.552 | AE13: =AC13+AD13 -> 1831.002 | AF13: =(IF(B13="",(S13*(1-$AF$1)),(IF(B13=1,(S13*(1-$AF$1)),(IF(B13=2,(S13*(1-0.15)),(IF(B13=3,(S13*(1-0.1)),(IF(B13=4,(S13*(1)))))))))))) -> 1541.31 | AG13: =AF13*0.16 -> 246.6096 | AH13: =AF13+AG13 -> 1787.9196 | AI13: =(IF(B13="",(S13*(1-$AI$1)),(IF(B13=1,(S13*(1-$AI$1)),(IF(B13=2,(S13*(1-0.15)),(IF(B13=3,(S13*(1-0.1)),(IF(B13=4,(S13*(1)))))))))))) -> 1485.6 | AJ13: =AI13*0.16 -> 237.696 | AK13: =AI13+AJ13 -> 1723.296 | AL13: =IFERROR(__xludf.DUMMYFUNCTION("""COMPUTED_VALUE"""),1.0) -> 1 | AN13: =IFERROR(__xludf.DUMMYFUNCTION("""COMPUTED_VALUE""")," C") -> C | AO13: =IFERROR(__xludf.DUMMYFUNCTION("""COMPUTED_VALUE""")," AN02") -> AN02 | AP13: =IFERROR(__xludf.DUMMYFUNCTION("""COMPUTED_VALUE""")," GAL") -> GAL | AQ13: =IFERROR(__xludf.DUMMYFUNCTION("""COMPUTED_VALUE""")," REF") -> REF | AR13: =IFERROR(__xludf.DUMMYFUNCTION("""COMPUTED_VALUE""")," ANTIADHERENTE ""A"" GALÓN") -> ANTIADHERENTE "A" GALÓN | AS13: =IFERROR(__xludf.DUMMYFUNCTION("""COMPUTED_VALUE""")," ANTIADHERENTE A GALON") -> ANTIADHERENTE A GALON | AT13: =IFERROR(__xludf.DUMMYFUNCTION("""COMPUTED_VALUE"""),21.0) -> 21 | AY13: =IFERROR(__xludf.DUMMYFUNCTION("""COMPUTED_VALUE"""),744.0) -> 744 | AZ13: =IFERROR(__xludf.DUMMYFUNCTION("""COMPUTED_VALUE"""),538.0) -> 538 | BA13: =IFERROR(__xludf.DUMMYFUNCTION("""COMPUTED_VALUE"""),482.4) -> 482.4 | BB13: =IFERROR(__xludf.DUMMYFUNCTION("""COMPUTED_VALUE"""),482.4) -> 482.4 | BC13: =IFERROR(__xludf.DUMMYFUNCTION("""COMPUTED_VALUE"""),538.0) -> 538 | BD13: =IFERROR(__xludf.DUMMYFUNCTION("""COMPUTED_VALUE"""),565.0) -> 565 | BE13: =IFERROR(__xludf.DUMMYFUNCTION("""COMPUTED_VALUE"""),90.4) -> 90.4 | BF13: =IFERROR(__xludf.DUMMYFUNCTION("""COMPUTED_VALUE"""),655.4) -> 655.4 | BG13: =IFERROR(__xludf.DUMMYFUNCTION("""COMPUTED_VALUE"""),0.05018587360594796) -> 0.050185874 | BH13: =IFERROR(__xludf.DUMMYFUNCTION("""COMPUTED_VALUE"""),536.75) -> 536.75 | BI13: =IFERROR(__xludf.DUMMYFUNCTION("""COMPUTED_VALUE"""),85.88) -> 85.88 | BJ13: =IFERROR(__xludf.DUMMYFUNCTION("""COMPUTED_VALUE"""),622.63) -> 622.63 | BK13: =IFERROR(__xludf.DUMMYFUNCTION("""COMPUTED_VALUE"""),508.5) -> 508.5 | BL13: =IFERROR(__xludf.DUMMYFUNCTION("""COMPUTED_VALUE"""),81.36) -> 81.36 | BM13: =IFERROR(__xludf.DUMMYFUNCTION("""COMPUTED_VALUE"""),589.86) -> 589.86 | BN13: =IFERROR(__xludf.DUMMYFUNCTION("""COMPUTED_VALUE"""),480.25) -> 480.25 | BO13: =IFERROR(__xludf.DUMMYFUNCTION("""COMPUTED_VALUE"""),76.84) -> 76.84 | BP13: =IFERROR(__xludf.DUMMYFUNCTION("""COMPUTED_VALUE"""),557.09) -> 557.09 | BQ13: =IFERROR(__xludf.DUMMYFUNCTION("""COMPUTED_VALUE"""),468.95) -> 468.95 | BR13: =IFERROR(__xludf.DUMMYFUNCTION("""COMPUTED_VALUE"""),75.032) -> 75.032 | BS13: =IFERROR(__xludf.DUMMYFUNCTION("""COMPUTED_VALUE"""),543.982) -> 543.982 | BT13: =IFERROR(__xludf.DUMMYFUNCTION("""COMPUTED_VALUE"""),452.0) -> 452 | BU13: =IFERROR(__xludf.DUMMYFUNCTION("""COMPUTED_VALUE"""),72.32000000000001) -> 72.32 | BV13: =IFERROR(__xludf.DUMMYFUNCTION("""COMPUTED_VALUE"""),524.32) -> 524.32
A14: 1 | C14: P | D14: AM10 | E14: PZA | F14: REF | G14: ACOMODADOR DE TORTILLAS CUADRUPLEX | H14: ACOMODADOR DE TORTILLAS CUADRUPLEX | I14: =IF(D14="","",LEN(H14)) -> 34 | N14: 4097 | O14: 4424 | P14: 4777.92 | Q14: 4777.92 | R14: 5319 | S14: 5585 | T14: =S14*0.16 -> 893.6 | U14: =S14+T14 -> 6478.6 | V14: =(S14-R14)/R14 -> 0.0500094 | W14: =(IF(B14="",(S14*(1-$W$1)),(IF(B14=1,(S14*(1-$W$1)),(IF(B14=2,(S14*(1-$W$1)),(IF(B14=3,(S14*(1-$W$1)),(IF(B14=4,(S14*(1)))))))))))) -> 5305.75 | X14: =W14*0.16 -> 848.92 | Y14: =W14+X14 -> 6154.67 | Z14: =(IF(B14="",(S14*(1-$Z$1)),(IF(B14=1,(S14*(1-$Z$1)),(IF(B14=2,(S14*(1-$Z$1)),(IF(B14=3,(S14*(1-$Z$1)),(IF(B14=4,(S14*(1)))))))))))) -> 5026.5 | AA14: =Z14*0.16 -> 804.24 | AB14: =Z14+AA14 -> 5830.74 | AC14: =(IF(B14="",(S14*(1-$AC$1)),(IF(B14=1,(S14*(1-$AC$1)),(IF(B14=2,(S14*(1-0.15)),(IF(B14=3,(S14*(1-0.1)),(IF(B14=4,(S14*(1)))))))))))) -> 4747.25 | AD14: =AC14*0.16 -> 759.56 | AE14: =AC14+AD14 -> 5506.81 | AF14: =(IF(B14="",(S14*(1-$AF$1)),(IF(B14=1,(S14*(1-$AF$1)),(IF(B14=2,(S14*(1-0.15)),(IF(B14=3,(S14*(1-0.1)),(IF(B14=4,(S14*(1)))))))))))) -> 4635.55 | AG14: =AF14*0.16 -> 741.688 | AH14: =AF14+AG14 -> 5377.238 | AI14: =(IF(B14="",(S14*(1-$AI$1)),(IF(B14=1,(S14*(1-$AI$1)),(IF(B14=2,(S14*(1-0.15)),(IF(B14=3,(S14*(1-0.1)),(IF(B14=4,(S14*(1)))))))))))) -> 4468 | AJ14: =AI14*0.16 -> 714.88 | AK14: =AI14+AJ14 -> 5182.88 | AL14: =IFERROR(__xludf.DUMMYFUNCTION("""COMPUTED_VALUE"""),1.0) -> 1 | AN14: =IFERROR(__xludf.DUMMYFUNCTION("""COMPUTED_VALUE""")," C") -> C | AO14: =IFERROR(__xludf.DUMMYFUNCTION("""COMPUTED_VALUE""")," AN03") -> AN03 | AP14: =IFERROR(__xludf.DUMMYFUNCTION("""COMPUTED_VALUE""")," LTR") -> LTR | AQ14: =IFERROR(__xludf.DUMMYFUNCTION("""COMPUTED_VALUE""")," REF") -> REF | AR14: =IFERROR(__xludf.DUMMYFUNCTION("""COMPUTED_VALUE""")," ANTIADHERENTE ""A"" LITRO") -> ANTIADHERENTE "A" LITRO | AS14: =IFERROR(__xludf.DUMMYFUNCTION("""COMPUTED_VALUE""")," ANTIADHERENTE A LITRO") -> ANTIADHERENTE A LITRO | AT14: =IFERROR(__xludf.DUMMYFUNCTION("""COMPUTED_VALUE"""),21.0) -> 21 | AY14: =IFERROR(__xludf.DUMMYFUNCTION("""COMPUTED_VALUE"""),182.0) -> 182 | AZ14: =IFERROR(__xludf.DUMMYFUNCTION("""COMPUTED_VALUE"""),134.0) -> 134 | BA14: =IFERROR(__xludf.DUMMYFUNCTION("""COMPUTED_VALUE"""),120.6) -> 120.6 | BB14: =IFERROR(__xludf.DUMMYFUNCTION("""COMPUTED_VALUE"""),120.6) -> 120.6 | BC14: =IFERROR(__xludf.DUMMYFUNCTION("""COMPUTED_VALUE"""),134.0) -> 134 | BD14: =IFERROR(__xludf.DUMMYFUNCTION("""COMPUTED_VALUE"""),141.0) -> 141 | BE14: =IFERROR(__xludf.DUMMYFUNCTION("""COMPUTED_VALUE"""),22.56) -> 22.56 | BF14: =IFERROR(__xludf.DUMMYFUNCTION("""COMPUTED_VALUE"""),163.56) -> 163.56 | BG14: =IFERROR(__xludf.DUMMYFUNCTION("""COMPUTED_VALUE"""),0.05223880597014925) -> 0.052238806 | BH14: =IFERROR(__xludf.DUMMYFUNCTION("""COMPUTED_VALUE"""),133.95) -> 133.95 | BI14: =IFERROR(__xludf.DUMMYFUNCTION("""COMPUTED_VALUE"""),21.432) -> 21.432 | BJ14: =IFERROR(__xludf.DUMMYFUNCTION("""COMPUTED_VALUE"""),155.38199999999998) -> 155.382 | BK14: =IFERROR(__xludf.DUMMYFUNCTION("""COMPUTED_VALUE"""),126.9) -> 126.9 | BL14: =IFERROR(__xludf.DUMMYFUNCTION("""COMPUTED_VALUE"""),20.304000000000002) -> 20.304 | BM14: =IFERROR(__xludf.DUMMYFUNCTION("""COMPUTED_VALUE"""),147.204) -> 147.204 | BN14: =IFERROR(__xludf.DUMMYFUNCTION("""COMPUTED_VALUE"""),119.85) -> 119.85 | BO14: =IFERROR(__xludf.DUMMYFUNCTION("""COMPUTED_VALUE"""),19.176) -> 19.176 | BP14: =IFERROR(__xludf.DUMMYFUNCTION("""COMPUTED_VALUE"""),139.02599999999998) -> 139.026 | BQ14: =IFERROR(__xludf.DUMMYFUNCTION("""COMPUTED_VALUE"""),117.03) -> 117.03 | BR14: =IFERROR(__xludf.DUMMYFUNCTION("""COMPUTED_VALUE"""),18.724800000000002) -> 18.7248 | BS14: =IFERROR(__xludf.DUMMYFUNCTION("""COMPUTED_VALUE"""),135.7548) -> 135.7548 | BT14: =IFERROR(__xludf.DUMMYFUNCTION("""COMPUTED_VALUE"""),112.80000000000001) -> 112.8 | BU14: =IFERROR(__xludf.DUMMYFUNCTION("""COMPUTED_VALUE"""),18.048000000000002) -> 18.048 | BV14: =IFERROR(__xludf.DUMMYFUNCTION("""COMPUTED_VALUE"""),130.848) -> 130.848
A15: 1 | C15: P | D15: AM01 | E15: PZA | F15: REF | G15: ACOMODADOR DE TORTILLAS ESTÁNDAR (10-17 CM.) | H15: ACOMODADOR DE TORTILLAS STD 10-17 CM | I15: =IF(D15="","",LEN(H15)) -> 36 | N15: 780 | O15: 842 | P15: 909.36 | Q15: 909.36 | R15: 1013 | S15: 1064 | T15: =S15*0.16 -> 170.24 | U15: =S15+T15 -> 1234.24 | V15: =(S15-R15)/R15 -> 0.050345508 | W15: =(IF(B15="",(S15*(1-$W$1)),(IF(B15=1,(S15*(1-$W$1)),(IF(B15=2,(S15*(1-$W$1)),(IF(B15=3,(S15*(1-$W$1)),(IF(B15=4,(S15*(1)))))))))))) -> 1010.8 | X15: =W15*0.16 -> 161.728 | Y15: =W15+X15 -> 1172.528 | Z15: =(IF(B15="",(S15*(1-$Z$1)),(IF(B15=1,(S15*(1-$Z$1)),(IF(B15=2,(S15*(1-$Z$1)),(IF(B15=3,(S15*(1-$Z$1)),(IF(B15=4,(S15*(1)))))))))))) -> 957.6 | AA15: =Z15*0.16 -> 153.216 | AB15: =Z15+AA15 -> 1110.816 | AC15: =(IF(B15="",(S15*(1-$AC$1)),(IF(B15=1,(S15*(1-$AC$1)),(IF(B15=2,(S15*(1-0.15)),(IF(B15=3,(S15*(1-0.1)),(IF(B15=4,(S15*(1)))))))))))) -> 904.4 | AD15: =AC15*0.16 -> 144.704 | AE15: =AC15+AD15 -> 1049.104 | AF15: =(IF(B15="",(S15*(1-$AF$1)),(IF(B15=1,(S15*(1-$AF$1)),(IF(B15=2,(S15*(1-0.15)),(IF(B15=3,(S15*(1-0.1)),(IF(B15=4,(S15*(1)))))))))))) -> 883.12 | AG15: =AF15*0.16 -> 141.2992 | AH15: =AF15+AG15 -> 1024.4192 | AI15: =(IF(B15="",(S15*(1-$AI$1)),(IF(B15=1,(S15*(1-$AI$1)),(IF(B15=2,(S15*(1-0.15)),(IF(B15=3,(S15*(1-0.1)),(IF(B15=4,(S15*(1)))))))))))) -> 851.2 | AJ15: =AI15*0.16 -> 136.192 | AK15: =AI15+AJ15 -> 987.392 | AL15: =IFERROR(__xludf.DUMMYFUNCTION("""COMPUTED_VALUE"""),1.0) -> 1 | AN15: =IFERROR(__xludf.DUMMYFUNCTION("""COMPUTED_VALUE""")," C") -> C | AO15: =IFERROR(__xludf.DUMMYFUNCTION("""COMPUTED_VALUE""")," AN04") -> AN04 | AP15: =IFERROR(__xludf.DUMMYFUNCTION("""COMPUTED_VALUE""")," CUB") -> CUB | AQ15: =IFERROR(__xludf.DUMMYFUNCTION("""COMPUTED_VALUE""")," REF") -> REF | AR15: =IFERROR(__xludf.DUMMYFUNCTION("""COMPUTED_VALUE""")," ANTIADHERENTE ""B"" 19 LITROS") -> ANTIADHERENTE "B" 19 LITROS | AS15: =IFERROR(__xludf.DUMMYFUNCTION("""COMPUTED_VALUE""")," ANTIADHERENTE B 19 LITROS") -> ANTIADHERENTE B 19 LITROS | AT15: =IFERROR(__xludf.DUMMYFUNCTION("""COMPUTED_VALUE"""),25.0) -> 25 | AY15: =IFERROR(__xludf.DUMMYFUNCTION("""COMPUTED_VALUE"""),2567.0) -> 2567 | AZ15: =IFERROR(__xludf.DUMMYFUNCTION("""COMPUTED_VALUE"""),1763.0) -> 1763 | BA15: =IFERROR(__xludf.DUMMYFUNCTION("""COMPUTED_VALUE"""),1675.8) -> 1675.8 | BB15: =IFERROR(__xludf.DUMMYFUNCTION("""COMPUTED_VALUE"""),1675.8) -> 1675.8 | BC15: =IFERROR(__xludf.DUMMYFUNCTION("""COMPUTED_VALUE"""),1866.0) -> 1866 | BD15: =IFERROR(__xludf.DUMMYFUNCTION("""COMPUTED_VALUE"""),1959.0) -> 1959 | BE15: =IFERROR(__xludf.DUMMYFUNCTION("""COMPUTED_VALUE"""),313.44) -> 313.44 | BF15: =IFERROR(__xludf.DUMMYFUNCTION("""COMPUTED_VALUE"""),2272.44) -> 2272.44 | BG15: =IFERROR(__xludf.DUMMYFUNCTION("""COMPUTED_VALUE"""),0.04983922829581994) -> 0.049839228 | BH15: =IFERROR(__xludf.DUMMYFUNCTION("""COMPUTED_VALUE"""),1861.05) -> 1861.05 | BI15: =IFERROR(__xludf.DUMMYFUNCTION("""COMPUTED_VALUE"""),297.768) -> 297.768 | BJ15: =IFERROR(__xludf.DUMMYFUNCTION("""COMPUTED_VALUE"""),2158.8179999999998) -> 2158.818 | BK15: =IFERROR(__xludf.DUMMYFUNCTION("""COMPUTED_VALUE"""),1763.1000000000001) -> 1763.1 | BL15: =IFERROR(__xludf.DUMMYFUNCTION("""COMPUTED_VALUE"""),282.096) -> 282.096 | BM15: =IFERROR(__xludf.DUMMYFUNCTION("""COMPUTED_VALUE"""),2045.1960000000001) -> 2045.196 | BN15: =IFERROR(__xludf.DUMMYFUNCTION("""COMPUTED_VALUE"""),1665.1499999999999) -> 1665.15 | BO15: =IFERROR(__xludf.DUMMYFUNCTION("""COMPUTED_VALUE"""),266.424) -> 266.424 | BP15: =IFERROR(__xludf.DUMMYFUNCTION("""COMPUTED_VALUE"""),1931.5739999999998) -> 1931.574 | BQ15: =IFERROR(__xludf.DUMMYFUNCTION("""COMPUTED_VALUE"""),1625.97) -> 1625.97 | BR15: =IFERROR(__xludf.DUMMYFUNCTION("""COMPUTED_VALUE"""),260.15520000000004) -> 260.1552 | BS15: =IFERROR(__xludf.DUMMYFUNCTION("""COMPUTED_VALUE"""),1886.1252) -> 1886.1252 | BT15: =IFERROR(__xludf.DUMMYFUNCTION("""COMPUTED_VALUE"""),1567.2) -> 1567.2 | BU15: =IFERROR(__xludf.DUMMYFUNCTION("""COMPUTED_VALUE"""),250.752) -> 250.752 | BV15: =IFERROR(__xludf.DUMMYFUNCTION("""COMPUTED_VALUE"""),1817.952) -> 1817.952
A16: 1 | C16: P | D16: AM02 | E16: PZA | F16: REF | G16: ACOMODADOR DE TORTILLAS TIPO PUEBLA | H16: ACOMODADOR DE TORTILLAS TIPO PUEBLA | I16: =IF(D16="","",LEN(H16)) -> 36 | N16: 898 | O16: 969 | P16: 1046.52 | Q16: 1046.52 | R16: 1166 | S16: 1224 | T16: =S16*0.16 -> 195.84 | U16: =S16+T16 -> 1419.84 | V16: =(S16-R16)/R16 -> 0.04974271 | W16: =(IF(B16="",(S16*(1-$W$1)),(IF(B16=1,(S16*(1-$W$1)),(IF(B16=2,(S16*(1-$W$1)),(IF(B16=3,(S16*(1-$W$1)),(IF(B16=4,(S16*(1)))))))))))) -> 1162.8 | X16: =W16*0.16 -> 186.048 | Y16: =W16+X16 -> 1348.848 | Z16: =(IF(B16="",(S16*(1-$Z$1)),(IF(B16=1,(S16*(1-$Z$1)),(IF(B16=2,(S16*(1-$Z$1)),(IF(B16=3,(S16*(1-$Z$1)),(IF(B16=4,(S16*(1)))))))))))) -> 1101.6 | AA16: =Z16*0.16 -> 176.256 | AB16: =Z16+AA16 -> 1277.856 | AC16: =(IF(B16="",(S16*(1-$AC$1)),(IF(B16=1,(S16*(1-$AC$1)),(IF(B16=2,(S16*(1-0.15)),(IF(B16=3,(S16*(1-0.1)),(IF(B16=4,(S16*(1)))))))))))) -> 1040.4 | AD16: =AC16*0.16 -> 166.464 | AE16: =AC16+AD16 -> 1206.864 | AF16: =(IF(B16="",(S16*(1-$AF$1)),(IF(B16=1,(S16*(1-$AF$1)),(IF(B16=2,(S16*(1-0.15)),(IF(B16=3,(S16*(1-0.1)),(IF(B16=4,(S16*(1)))))))))))) -> 1015.92 | AG16: =AF16*0.16 -> 162.5472 | AH16: =AF16+AG16 -> 1178.4672 | AI16: =(IF(B16="",(S16*(1-$AI$1)),(IF(B16=1,(S16*(1-$AI$1)),(IF(B16=2,(S16*(1-0.15)),(IF(B16=3,(S16*(1-0.1)),(IF(B16=4,(S16*(1)))))))))))) -> 979.2 | AJ16: =AI16*0.16 -> 156.672 | AK16: =AI16+AJ16 -> 1135.872 | AL16: =IFERROR(__xludf.DUMMYFUNCTION("""COMPUTED_VALUE"""),1.0) -> 1 | AN16: =IFERROR(__xludf.DUMMYFUNCTION("""COMPUTED_VALUE""")," C") -> C | AO16: =IFERROR(__xludf.DUMMYFUNCTION("""COMPUTED_VALUE""")," AN05") -> AN05 | AP16: =IFERROR(__xludf.DUMMYFUNCTION("""COMPUTED_VALUE""")," GAL") -> GAL | AQ16: =IFERROR(__xludf.DUMMYFUNCTION("""COMPUTED_VALUE""")," REF") -> REF | AR16: =IFERROR(__xludf.DUMMYFUNCTION("""COMPUTED_VALUE""")," ANTIADHERENTE ""B"" GALÓN") -> ANTIADHERENTE "B" GALÓN | AS16: =IFERROR(__xludf.DUMMYFUNCTION("""COMPUTED_VALUE""")," ANTIADHERENTE B GALON") -> ANTIADHERENTE B GALON | AT16: =IFERROR(__xludf.DUMMYFUNCTION("""COMPUTED_VALUE"""),21.0) -> 21 | AY16: =IFERROR(__xludf.DUMMYFUNCTION("""COMPUTED_VALUE"""),540.0) -> 540 | AZ16: =IFERROR(__xludf.DUMMYFUNCTION("""COMPUTED_VALUE"""),371.0) -> 371 | BA16: =IFERROR(__xludf.DUMMYFUNCTION("""COMPUTED_VALUE"""),352.8) -> 352.8 | BB16: =IFERROR(__xludf.DUMMYFUNCTION("""COMPUTED_VALUE"""),352.8) -> 352.8 | BC16: =IFERROR(__xludf.DUMMYFUNCTION("""COMPUTED_VALUE"""),393.0) -> 393 | BD16: =IFERROR(__xludf.DUMMYFUNCTION("""COMPUTED_VALUE"""),413.0) -> 413 | BE16: =IFERROR(__xludf.DUMMYFUNCTION("""COMPUTED_VALUE"""),66.08) -> 66.08 | BF16: =IFERROR(__xludf.DUMMYFUNCTION("""COMPUTED_VALUE"""),479.08) -> 479.08 | BG16: =IFERROR(__xludf.DUMMYFUNCTION("""COMPUTED_VALUE"""),0.05089058524173028) -> 0.050890585 | BH16: =IFERROR(__xludf.DUMMYFUNCTION("""COMPUTED_VALUE"""),392.34999999999997) -> 392.35 | BI16: =IFERROR(__xludf.DUMMYFUNCTION("""COMPUTED_VALUE"""),62.775999999999996) -> 62.776 | BJ16: =IFERROR(__xludf.DUMMYFUNCTION("""COMPUTED_VALUE"""),455.126) -> 455.126 | BK16: =IFERROR(__xludf.DUMMYFUNCTION("""COMPUTED_VALUE"""),371.7) -> 371.7 | BL16: =IFERROR(__xludf.DUMMYFUNCTION("""COMPUTED_VALUE"""),59.472) -> 59.472 | BM16: =IFERROR(__xludf.DUMMYFUNCTION("""COMPUTED_VALUE"""),431.17199999999997) -> 431.172 | BN16: =IFERROR(__xludf.DUMMYFUNCTION("""COMPUTED_VALUE"""),351.05) -> 351.05 | BO16: =IFERROR(__xludf.DUMMYFUNCTION("""COMPUTED_VALUE"""),56.168000000000006) -> 56.168 | BP16: =IFERROR(__xludf.DUMMYFUNCTION("""COMPUTED_VALUE"""),407.218) -> 407.218 | BQ16: =IFERROR(__xludf.DUMMYFUNCTION("""COMPUTED_VALUE"""),342.78999999999996) -> 342.79 | BR16: =IFERROR(__xludf.DUMMYFUNCTION("""COMPUTED_VALUE"""),54.846399999999996) -> 54.8464 | BS16: =IFERROR(__xludf.DUMMYFUNCTION("""COMPUTED_VALUE"""),397.6364) -> 397.6364 | BT16: =IFERROR(__xludf.DUMMYFUNCTION("""COMPUTED_VALUE"""),330.40000000000003) -> 330.4 | BU16: =IFERROR(__xludf.DUMMYFUNCTION("""COMPUTED_VALUE"""),52.864000000000004) -> 52.864 | BV16: =IFERROR(__xludf.DUMMYFUNCTION("""COMPUTED_VALUE"""),383.264) -> 383.264
